Workbook

Sheet Canonical_Data_Template
A1: Canonical data-entry template
A2: Yellow columns are sourced/enriched inputs; grey columns contain formulas. Paste standardized facts from row 5.
A4: source_record_id | B4: source_version_id | C4: year | D4: month | E4: region_code | F4: region_name | G4: asl_code | H4: channel | I4: aic | J4: atc1 | K4: atc2 | L4: atc3 | M4: atc4 | N4: atc5 | O4: product_description_raw | P4: brand_name | Q4: active_substance | R4: quantity_packs | S4: total_cost_eur | T4: biosimilar_flag | U4: originator_flag | V4: units_per_pack | W4: strength_value_mg | X4: volume_per_unit_ml | Y4: ddd_value_mg | Z4: unit_cost_eur | AA4: total_content_mg | AB4: ddds_per_pack | AC4: cost_per_mg | AD4: cost_per_ddd | AE4: mapping_confidence | AF4: quality_status
Z5: =IFERROR(S5/R5,"") | AA5: =IF(AND(V5<>"",W5<>""),V5*W5,"") | AB5: =IFERROR(AA5/Y5,"") | AC5: =IFERROR(Z5/AA5,"") | AD5: =IFERROR(Z5/AB5,"")
Z6: =IFERROR(S6/R6,"") | AA6: =IF(AND(V6<>"",W6<>""),V6*W6,"") | AB6: =IFERROR(AA6/Y6,"") | AC6: =IFERROR(Z6/AA6,"") | AD6: =IFERROR(Z6/AB6,"")
Z7: =IFERROR(S7/R7,"") | AA7: =IF(AND(V7<>"",W7<>""),V7*W7,"") | AB7: =IFERROR(AA7/Y7,"") | AC7: =IFERROR(Z7/AA7,"") | AD7: =IFERROR(Z7/AB7,"")
Z8: =IFERROR(S8/R8,"") | AA8: =IF(AND(V8<>"",W8<>""),V8*W8,"") | AB8: =IFERROR(AA8/Y8,"") | AC8: =IFERROR(Z8/AA8,"") | AD8: =IFERROR(Z8/AB8,"")
Z9: =IFERROR(S9/R9,"") | AA9: =IF(AND(V9<>"",W9<>""),V9*W9,"") | AB9: =IFERROR(AA9/Y9,"") | AC9: =IFERROR(Z9/AA9,"") | AD9: =IFERROR(Z9/AB9,"")
Z10: =IFERROR(S10/R10,"") | AA10: =IF(AND(V10<>"",W10<>""),V10*W10,"") | AB10: =IFERROR(AA10/Y10,"") | AC10: =IFERROR(Z10/AA10,"") | AD10: =IFERROR(Z10/AB10,"")
Z11: =IFERROR(S11/R11,"") | AA11: =IF(AND(V11<>"",W11<>""),V11*W11,"") | AB11: =IFERROR(AA11/Y11,"") | AC11: =IFERROR(Z11/AA11,"") | AD11: =IFERROR(Z11/AB11,"")
Z12: =IFERROR(S12/R12,"") | AA12: =IF(AND(V12<>"",W12<>""),V12*W12,"") | AB12: =IFERROR(AA12/Y12,"") | AC12: =IFERROR(Z12/AA12,"") | AD12: =IFERROR(Z12/AB12,"")
Z13: =IFERROR(S13/R13,"") | AA13: =IF(AND(V13<>"",W13<>""),V13*W13,"") | AB13: =IFERROR(AA13/Y13,"") | AC13: =IFERROR(Z13/AA13,"") | AD13: =IFERROR(Z13/AB13,"")
Z14: =IFERROR(S14/R14,"") | AA14: =IF(AND(V14<>"",W14<>""),V14*W14,"") | AB14: =IFERROR(AA14/Y14,"") | AC14: =IFERROR(Z14/AA14,"") | AD14: =IFERROR(Z14/AB14,"")
Z15: =IFERROR(S15/R15,"") | AA15: =IF(AND(V15<>"",W15<>""),V15*W15,"") | AB15: =IFERROR(AA15/Y15,"") | AC15: =IFERROR(Z15/AA15,"") | AD15: =IFERROR(Z15/AB15,"")
Z16: =IFERROR(S16/R16,"") | AA16: =IF(AND(V16<>"",W16<>""),V16*W16,"") | AB16: =IFERROR(AA16/Y16,"") | AC16: =IFERROR(Z16/AA16,"") | AD16: =IFERROR(Z16/AB16,"")
... Z54: =IFERROR(S54/R54,"") | AA54: =IF(AND(V54<>"",W54<>""),V54*W54,"") | AB54: =IFERROR(AA54/Y54,"") | AC54: =IFERROR(Z54/AA54,"") | AD54: =IFERROR(Z54/AB54,"")

Sheet Module_Readiness_Verdict
A1: Per-Module Data Readiness — re-verified 21 Aug 2026
A2: Re-checked column-by-column against both Combined data.xlsx (8 sheets) and this workbook's reference sheets. M2 updated with the full parser result (was reported as ~70%/12.1% before the parser run; now 73.8% products / 77.3% spend, verified against all 5,882 real products).
A4: Module | B4: Verdict | C4: Basis (re-verified, not carried over)
A5: M1 Spend | B5: Sufficient now | C5: 529,979 national rows, all 21 regions/provinces confirmed by name; 261,153 Abruzzo rows, 4 ASL, 2024-2026. Unchanged from prior check.
A6: M2 Biosimilar/LOE | B6: Partial - improved, plus a real enrichment worklist | C6: UPDATED 21 Aug 2026: prior verified state unchanged (73.8% products / 77.3% spend via layered parser). Codex independently found Regione Emilia-Romagna's public Listino Ordini Farmaci (opendata-intercenter.regione.emilia-romagna.it) with 616 exact AIC matches against our 1,541 unresolved products (spend EUR 176.5M), but correctly did NOT count these as normalized - no structured contents-per-pack field, so €/mg still isn't computable from this source alone. Treated as a candidate enrichment worklist, not new coverage, until our own parser is tested against these specific rows (pending - see Source_Catalog).
A7: M3 Registry/File F | B7: Not present - now exhaustively searched | C7: UPDATED 21 Aug 2026: Codex searched aifa.gov.it, salute.gov.it, dati.gov.it, dati.lombardia.it and SIFO specifically for File F record-level data. Found: NSIS submission specs (institutional access only), a public galenic-formula REGISTRY (9,332 rows - formula identity only, no activity/quantity data), and two 2019 Lombardia aggregate datasets that are old, aggregate, and currently inaccessible at row level (DNS/403 errors, confirmed not bypassed). Verdict unchanged: still client-required, but now backed by a documented, thorough search rather than an assumption.
A8: M4 Stock/Shortage | B8: Data source confirmed, not yet ingested | C8: UPDATED 21 Aug 2026 (Codex research, independently re-checked): AIFA's shortage CSV is live and real — https://www.aifa.gov.it/documents/20142/847339/elenco_medicinali_carenti.csv — 2,523 records, 2,521 unique AICs, 13 columns, file-internal update date 18 Aug 2026. Still does not cover hospital-level batch/inventory/quantity-on-hand — that portion remains client-required. This closes the 'shortage risk' half of M4, not the 'working capital at risk' half. INDEPENDENTLY RE-VERIFIED by Claude (not just Codex) 21 Aug 2026: fetched the live URL directly, confirmed the file itself states 'aggiornato al 18/08/2026', confirmed all 13 column names match exactly, confirmed the two-line preamble format. NOT independently confirmed: the exact 2,523/2,521 row/AIC count — that figure is still Codex-reported only. FURTHER UPDATE 21 Aug 2026: AIFA quality-defects source (S25) confirmed real by Claude - genuine bulk lot-level restrictive-measures data, separate from and additive to the shortage list (S17). Exact current-period row count not yet independently recounted - treat specific figures as Codex-reported pending confirmation.
A9: M5 Compounding waste | B9: Not present - now exhaustively searched | C9: UPDATED 21 Aug 2026: Codex found real SIFO evidence (a 2011 Piemonte policy estimate, a 2024 practice survey with 38 responses, and a single-centre durvalumab case study - 114 cycles, EUR 17,340/year saving at one site) - genuinely useful for the SALES NARRATIVE (proves the waste is real and measurable) but none is a public multi-centre waste dataset. Verdict unchanged: still client-required, now with citable evidence for why the module matters.
A10: M6 Cross-authority | B10: Sufficient for region-level; partial below that | C10: All 21 regions ready for region-vs-region ATC-level comparison today. Abruzzo's 4 ASL ready for full AIC-level comparison. Any other region's ASL-level detail still needs its own data-sharing agreement. Unchanged from prior check.
A11: M7 Horizon/pipeline | B11: Partial - EMA ready, AIFA CSE pipeline now verified | C11: UPDATED 21 Aug 2026 (Codex research, independently re-checked): EMA publishes a real monthly under-evaluation XLSX (77 applications) plus three JSON exports refreshed twice daily (news/medicines/post-authorisation) - genuinely bulk, genuinely structured. AIFA's C(nn) monthly lists are a usable pipeline proxy (51 in-evaluation, 2,190 evaluated rows) but explicitly do NOT cover the full ongoing price/reimbursement negotiation queue - that remains unverified as a public source. FURTHER UPDATE 21 Aug 2026: AIFA's monthly CSE outcomes list (Esiti UPR) independently verified EXACT by Claude - 116 procedures, 89 still-in-exchange / 21 sent to Board / 6 concluded, all counted by code against the real fetched PDF. This is a real, reproducible monthly reimbursement-pipeline feed (S23) - stronger than the earlier C(nn) proxy alone. Comprehensive ongoing-negotiation register (every possible negotiation, not just CSE-session outcomes) still not verified as public.

Sheet Implementation_Backlog
A1: Implementation backlog
A2: Evidence-led sequence from public observatory to multi-region deployment.
A4: Phase | B4: Deliverable | C4: Key work | D4: Exit criterion
A5: 0 | B5: Governance prerequisites | C5: Intended purpose, legal opinion, source licensing and owners | D5: Written approvals
A6: 1 | B6: National public observatory | C6: 2016+ AIFA ingestion, versions, ATC, variance | D6: Reproducible M1/M6 outputs
A7: 2 | B7: Abruzzo canonical adapter | C7: Map fields, reconcile totals, preserve lineage | D7: ASL/month/channel tie-out
A8: 3 | B8: Pack normalisation | C8: AIFA reference, parser, validation queue, conditional licensed gaps | D8: Published coverage/error benchmark
A9: 4 | B9: M2 evidence engine | C9: Biosimilar mapping, DDD, LOE and review queue | D9: Back-test known variance
A10: 5 | B10: Paid diagnostic | C10: One authority, 12-24 months, opportunity worklist | D10: Authority validates numbers/workflow
A11: 6 | B11: M3-M5 extensions | C11: File F, inventory and compounding adapters | D11: Module controls pass
A12: 7 | B12: Regional multi-tenancy | C12: Isolation, roles, audit, scheduled refresh | D12: Security/onboarding acceptance

Sheet Missing_Data_Register
A1: Missing-data register
A2: Inputs required before complete production delivery.
A4: Priority | B4: Missing input | C4: Needed for | D4: Owner | E4: Resolution | F4: Acceptance criterion
A5: RESOLVED | B5: AIFA coverage/parser benchmark | C5: M2 | D5: Data/pharmacy | E5: Stratified validation sample | F5: Verified 21 Aug 2026: 97.9% product-identity match, 12.1% usable qty+unit via AIFA structured file, ~70% via free-text parser (primary method). See AIC_Join_Coverage sheet.
A6: P0 | B6: Written intended-purpose/MDR opinion | C6: All | D6: Legal/regulatory | E6: External review | F6: Controlled statement and opinion
A7: P0 | B7: Pilot Region/ASL extracts and totals | C7: M1 | D7: Pilot authority | E7: Data-sharing agreement | F7: 12-24 months reconciled
A8: P1 | B8: Farmadati/equivalent for residual gaps | C8: M2 | D8: Product/legal | E8: Conditional licensing assessment | F8: Only if public assurance threshold unmet
A9: P1 | B9: WHO ATC/DDD structured release | C9: M2 | D9: Data engineering | E9: Load effective-dated reference | F9: Route-specific validation
A10: P1 | B10: Validated LOE event register | C10: M2 | D10: Pharmacy/procurement/legal | E10: Extract and confirm | F10: Source/status/verification on every event
A11: P1 | B11: Effective-dated biosimilar mapping | C11: M2,M6 | D11: Pharmacy steward | E11: Controlled reference | F11: Coverage and sign-off
A12: P1 | B12: File F/Registry specifications | C12: M3 | D12: Pilot authority | E12: Obtain layouts | F12: Privacy/schema acceptance
A13: P2 | B13: Inventory/batch/movement feed | C13: M4 | D13: Pilot authority | E13: Warehouse export | F13: Reconciliation to warehouse
A14: P2 | B14: Aggregate preparation logs | C14: M5 | D14: Pilot authority | E14: Non-patient extract | F14: Reconciled waste totals
A15: P2 | B15: Population/activity denominators | C15: M1,M6 | D15: ISTAT/Region | E15: Annual reference | F15: Period and denominator displayed
... A17: RESOLVED | B17: M7 EMA pipeline source | C17: M7 | D17: Data engineering | E17: EMA XLSX + JSON confirmed live (S18/S19) | F17: Ingest S18/S19; AIFA negotiation register remains unverified as public

Sheet Biosimilar_Summary
A1: Biosimilar penetration summary
A2: Formula-driven calculations from Biosimilar_Seed.
A4: ASL | B4: Biosimilar qty 2025 | C4: Originator qty 2025 | D4: Eligible qty | E4: Biosimilar penetration | F4: Biosimilar spend | G4: Originator spend
A5: AQ | B5: =SUMIFS(Biosimilar_Seed!$F$5:$F$12,Biosimilar_Seed!$C$5:$C$12,A5,Biosimilar_Seed!$B$5:$B$12,"Biosimilar") | C5: =SUMIFS(Biosimilar_Seed!$F$5:$F$12,Biosimilar_Seed!$C$5:$C$12,A5,Biosimilar_Seed!$B$5:$B$12,"Originator") | D5: =B5+C5 | E5: =IFERROR(B5/D5,"") | F5: =SUMIFS(Biosimilar_Seed!$D$5:$D$12,Biosimilar_Seed!$C$5:$C$12,A5,Biosimilar_Seed!$B$5:$B$12,"Biosimilar") | G5: =SUMIFS(Biosimilar_Seed!$D$5:$D$12,Biosimilar_Seed!$C$5:$C$12,A5,Biosimilar_Seed!$B$5:$B$12,"Originator")
A6: CH | B6: =SUMIFS(Biosimilar_Seed!$F$5:$F$12,Biosimilar_Seed!$C$5:$C$12,A6,Biosimilar_Seed!$B$5:$B$12,"Biosimilar") | C6: =SUMIFS(Biosimilar_Seed!$F$5:$F$12,Biosimilar_Seed!$C$5:$C$12,A6,Biosimilar_Seed!$B$5:$B$12,"Originator") | D6: =B6+C6 | E6: =IFERROR(B6/D6,"") | F6: =SUMIFS(Biosimilar_Seed!$D$5:$D$12,Biosimilar_Seed!$C$5:$C$12,A6,Biosimilar_Seed!$B$5:$B$12,"Biosimilar") | G6: =SUMIFS(Biosimilar_Seed!$D$5:$D$12,Biosimilar_Seed!$C$5:$C$12,A6,Biosimilar_Seed!$B$5:$B$12,"Originator")
A7: PE | B7: =SUMIFS(Biosimilar_Seed!$F$5:$F$12,Biosimilar_Seed!$C$5:$C$12,A7,Biosimilar_Seed!$B$5:$B$12,"Biosimilar") | C7: =SUMIFS(Biosimilar_Seed!$F$5:$F$12,Biosimilar_Seed!$C$5:$C$12,A7,Biosimilar_Seed!$B$5:$B$12,"Originator") | D7: =B7+C7 | E7: =IFERROR(B7/D7,"") | F7: =SUMIFS(Biosimilar_Seed!$D$5:$D$12,Biosimilar_Seed!$C$5:$C$12,A7,Biosimilar_Seed!$B$5:$B$12,"Biosimilar") | G7: =SUMIFS(Biosimilar_Seed!$D$5:$D$12,Biosimilar_Seed!$C$5:$C$12,A7,Biosimilar_Seed!$B$5:$B$12,"Originator")
A8: TE | B8: =SUMIFS(Biosimilar_Seed!$F$5:$F$12,Biosimilar_Seed!$C$5:$C$12,A8,Biosimilar_Seed!$B$5:$B$12,"Biosimilar") | C8: =SUMIFS(Biosimilar_Seed!$F$5:$F$12,Biosimilar_Seed!$C$5:$C$12,A8,Biosimilar_Seed!$B$5:$B$12,"Originator") | D8: =B8+C8 | E8: =IFERROR(B8/D8,"") | F8: =SUMIFS(Biosimilar_Seed!$D$5:$D$12,Biosimilar_Seed!$C$5:$C$12,A8,Biosimilar_Seed!$B$5:$B$12,"Biosimilar") | G8: =SUMIFS(Biosimilar_Seed!$D$5:$D$12,Biosimilar_Seed!$C$5:$C$12,A8,Biosimilar_Seed!$B$5:$B$12,"Originator")

Sheet Biosimilar_Seed
A1: Biosimilar comparison seed
A2: Abruzzo erythropoietin example demonstrating cross-ASL logic.
A4: Product | B4: Status | C4: ASL | D4: Spend 2025 | E4: Spend 2024 | F4: Qty 2025 | G4: Qty 2024
A5: BINOCRIT | B5: Biosimilar | C5: AQ | D5: 566473.26 | E5: 256116.06 | F5: 16056 | G5: 11389
A6: BINOCRIT | B6: Biosimilar | C6: CH | D6: 1014036.2 | E6: 391904.21 | F6: 23210 | G6: 25940
A7: BINOCRIT | B7: Biosimilar | C7: PE | D7: 536256.33 | E7: 170295.97 | F7: 10387 | G7: 8802
A8: BINOCRIT | B8: Biosimilar | C8: TE | D8: 642902.44 | E8: 237920.24 | F8: 18241 | G8: 10939
A9: EPREX | B9: Originator | C9: AQ | D9: 36772.86 | E9: 65356.72 | F9: 494 | G9: 694
A10: EPREX | B10: Originator | C10: CH | D10: 250837.27 | E10: 491920.33 | F10: 2795 | G10: 5501
A11: EPREX | B11: Originator | C11: PE | D11: 183516.23 | E11: 398699.73 | F11: 2112 | G11: 4451
A12: EPREX | B12: Originator | C12: TE | D12: 77350.18 | E12: 166703.02 | F12: 954 | G12: 1911

Sheet Patent_Expiry_Seed
A1: Patent-expiry seed register
A2: Initial Abruzzo workbook records; all dates require legal and commercial validation.
A4: ATC | B4: Active substance | C4: Class | D4: Expiry serial | E4: 2022 spend | F4: 2023 spend | G4: 2024 spend | H4: Average | I4: Status
A5: A10BD10 | B5: SAXAGLIPTIN E METFORMINA | C5: A/RR | D5: 46086 | E5: 488781 | F5: 364304 | G5: 315045 | H5: 389377 | I5: Indicative
A6: B02BD02 | B6: SIMOCTOCOG ALFA | C6: A/RRL/PT/PHT | D6: 46102 | E6: 10412078 | F6: 10279647 | G6: 8597932 | H6: 9763219 | I6: Indicative
A7: N03AX22 | B7: PERAMPANEL | C7: A/RR/PT/PHT | D7: 46181 | E7: 8752109 | F7: 9801577 | G7: 11077354 | H7: 9877013 | I7: Indicative
A8: A10BJ01 | B8: EXENATIDE | C8: A/RR/PHT | D8: 46195 | E8: 14042970 | F8: 11151163 | G8: 9177831 | H8: 11457321 | I8: Indicative
A9: H01CB05 | B9: PASIREOTIDE | C9: A/PHT/PT | D9: 46233 | E9: 8788364 | F9: 9848687 | G9: 10681079 | H9: 9772710 | I9: Indicative
A10: B01AE07 | B10: DABIGATRAN ETEXILATO | C10: A/RRL/PT/PHT | D10: 46234 | E10: 75253751 | F10: 72977817 | G10: 52957851 | H10: 67063140 | I10: Indicative
A11: N07XX08 | B11: TAFAMIDIS | C11: H/RRL | D11: 46343 | E11: 66789416 | F11: 123168492 | G11: 164405412 | H11: 118121107 | I11: Indicative
A12: B01AF02 | B12: APIXABAN | C12: A/RRL/PT/PHT | D12: 46346 | E12: 200210680 | F12: 241135880 | G12: 254501707 | H12: 231949422 | I12: Indicative
A13: J05AG05 | B13: RILPIVIRINA | C13: H/RNRL | D13: 46354 | E13: 2863692 | F13: 2261649 | G13: 1733669 | H13: 2286337 | I13: Indicative
A14: L04AG04 | B14: BELIMUMAB | C14: H/OSP | D14: 46371 | E14: 13347709 | F14: 15645120 | G14: 18732280 | H14: 15908370 | I14: Indicative

Sheet AIFA_AIC_Profile
A1: AIFA public AIC-reference profile
A2: Verified downloaded files; product enrichment, not regional utilisation.
A4: Measure | B4: Value | C4: Interpretation | D4: Source URL
A5: Product master bytes | B5: 82449042 | C5: National authorised-pack register | D5: https://www.aifa.gov.it/en/web/guest/liste-dei-farmaci
A6: Active-ingredient rows | B6: 72203 | C6: AIC-ingredient relations | D6: https://drive.aifa.gov.it/farmaci/PA_confezioni.csv
A7: Distinct AICs | B7: 58496 | C7: Observed identifiers | D7: https://drive.aifa.gov.it/farmaci/PA_confezioni.csv
A8: Rows with non-zero quantity | B8: 24034 | C8: Structured dosage quantity | D8: https://drive.aifa.gov.it/farmaci/PA_confezioni.csv
A9: Rows with usable unit | B9: 17586 | C9: Incomplete structured-unit coverage | D9: https://drive.aifa.gov.it/farmaci/PA_confezioni.csv
A10: Precedence | B10: AIFA > parser > licensed/manual | C10: Gap-based normalization strategy | D10: https://www.aifa.gov.it/en/web/guest/liste-dei-farmaci

Sheet National_Profile
A1: National public-data profile
A2: Supplied annual files; totals combine traceability and conventional expenditure.
A4: Year | B4: Rows | C4: Geographies | D4: Months | E4: Traceability spend | F4: Conventional spend | G4: Total spend | H4: YoY growth | I4: Top ATC | J4: ATC L spend
A5: 2023 | B5: 174595 | C5: 21 | D5: 12 | E5: 1.6427453e+10 | F5: 9.8721681e+09 | G5: 2.6299622e+10 | I5: L | J5: 7.3552654e+09
A6: 2024 | B6: 177749 | C6: 21 | D6: 12 | E6: 1.8068224e+10 | F6: 1.0031814e+10 | G6: 2.8100039e+10 | H6: =IFERROR(G6/G5-1,"") | I6: L | J6: 8.2004557e+09
A7: 2025 | B7: 177635 | C7: 21 | D7: 12 | E7: 1.9234884e+10 | F7: 1.0514261e+10 | G7: 2.9749145e+10 | H7: =IFERROR(G7/G6-1,"") | I7: L | J7: 8.8081291e+09

Sheet Regional_DB_Profile
A1: Abruzzo detailed database profile
A2: Observed in DB_Cruscotto_Farmaceutica.xlsx.
A4: Attribute | B4: Observed value | C4: Implication
A5: Rows | B5: 261153 | C5: Development corpus for adapter and parsing
A6: ASLs | B6: AQ, CH, PE, TE | C6: Internal authority comparison
A7: Years | B7: 2024-2026 | C7: Historical/current partial analysis
A8: Measures | B8: Q packs; C cost | C8: Volume and expenditure facts
A9: Product key | B9: COD AIC | C9: AIFA reference join
A10: Product text | B10: Descrizione prodotto | C10: Embedded pack/strength patterns
A11: Channels | B11: CO, DD, DPC and others | C11: Channel comparison
A12: Classification | B12: ATC1-ATC5 available | C12: Category-to-substance drilldown
A13: Existing flags | B13: Biosimilar, transparency, PHT, innovation, LOE | C13: Seeds requiring dated provenance
A14: Limitation | B14: Pack strength/size not separate | C14: AIFA join, parser, then licensed/manual gaps
A15: Governance | B15: Preserve raw source and lineage | C15: Never overwrite original data

Sheet Quality_Controls
A1: Quality and publication controls
A2: Critical failures quarantine records or suppress affected periods.
A4: Control | B4: Severity | C4: Scope | D4: Test | E4: Failure action
A5: Q01 Schema completeness | B5: Critical | C5: Every ingestion | D5: Required fields and types | E5: Reject version
A6: Q02 Uniqueness | B6: Critical | C6: Regional facts | D6: No duplicate source key | E6: Quarantine duplicates
A7: Q03 ATC hierarchy | B7: High | C7: All facts | D7: Parent-child consistency | E7: Repair or quarantine
A8: Q04 AIC format | B8: High | C8: Regional facts | D8: Nine digits as text | E8: Quarantine invalid AIC
A9: Q05 Financial reconciliation | B9: Critical | C9: Authority/period/channel | D9: Agreement to official total | E9: Do not publish
A10: Q06 Negative values | B10: Medium | C10: Quantity/cost | D10: Identify returns/corrections | E10: Retain and flag
A11: Q07 Mapping confidence | B11: High | C11: Normalised metrics | D11: Authoritative or validated | E11: Hide candidates
A12: Q08 DDD compatibility | B12: Critical | C12: Cost per DDD | D12: ATC/route/unit compatible | E12: Suppress metric
A13: Q09 Period completeness | B13: High | C13: Monthly feeds | D13: Expected perimeter present | E13: Suppress ranking
A14: Q10 Source revision | B14: Medium | C14: National publications | D14: Detect changed history | E14: Recalculate/version
A15: Q11 LOE status | B15: High | C15: Patent events | D15: Indicative vs confirmed explicit | E15: No legal certainty claim
A16: Q12 Privacy boundary | B16: Critical | C16: All modules | D16: No patient recommendation/identifier | E16: Reject output

Sheet Calculation_Rules
A1: Calculation rules
A2: Auditable formulas with publication guardrails.
A4: Rule | B4: Metric | C4: Formula/method | D4: Required inputs | E4: Guardrail | F4: Unit
A5: C01 | B5: Unit cost | C5: total_cost_eur / quantity_packs | D5: cost, quantity | E5: Blank if quantity=0 | F5: EUR/pack
A6: C02 | B6: Solid total content | C6: units_per_pack x strength x conversion | D6: units, strength, unit | E6: Validated single ingredient/allocation | F6: mg/pack
A7: C03 | B7: Concentration content | C7: units x volume x mg/mL | D7: units, volume, concentration | E7: Never infer fill volume | F7: mg/pack
A8: C04 | B8: Cost per mg | C8: unit cost / total content | D8: C01, content | E8: Authoritative/validated mapping only | F8: EUR/mg
A9: C05 | B9: DDDs per pack | C9: total content / WHO DDD | D9: content, DDD, route | E9: Compatible ATC/route only | F9: DDD/pack
A10: C06 | B10: Cost per DDD | C10: unit cost / DDDs per pack | D10: C01, C05 | E10: Suppress if incompatible | F10: EUR/DDD
A11: C07 | B11: Biosimilar penetration volume | C11: biosimilar quantity / eligible quantity | D11: quantity, mapping | E11: Effective-dated eligible perimeter | F11: %
A12: C08 | B12: Biosimilar penetration spend | C12: biosimilar spend / eligible spend | D12: cost, mapping | E12: Not interchangeable with volume | F12: %
A13: C09 | B13: YoY delta | C13: current comparable - prior comparable | D13: period, metric | E13: Like-for-like months/perimeter | F13: EUR/count/%
A14: C10 | B14: Variance signal | C14: materiality x deviation x persistence x quality | D14: peer distribution | E14: Review signal only | F14: 0-100
A15: C11 | B15: Expiry value at risk | C15: on-hand x acquisition cost | D15: inventory, batch, cost | E15: Configurable 30/60/90 days | F15: EUR
A16: C12 | B16: Reconciliation difference | C16: internal total - official total | D16: facts, control totals | E16: Resolve before publication | F16: EUR/%

Sheet Canonical_Fact
A1: Canonical fact schema
A2: Every adapter maps source data into this governed grain.
A4: Field | B4: Type | C4: Unit/code | D4: Required | E4: Source priority | F4: Validation | G4: Description
A5: source_record_id | B5: text | C5: native | D5: Yes | E5: Source | F5: Unique within version | G5: Immutable lineage key
A6: source_version_id | B6: text | C6: ingestion version | D6: Yes | E6: Pipeline | F6: Exists in provenance | G6: File/checksum/load link
A7: year | B7: integer | C7: YYYY | D7: Yes | E7: Source | F7: 2016-current+1 | G7: Reporting year
A8: month | B8: integer | C8: 46034 | D8: Yes | E8: Source | F8: 1 through 12 | G8: Reporting month
A9: region_code | B9: text | C9: ISTAT/NSIS | D9: Yes | E9: Source/map | F9: Controlled value | G9: Region identifier
A10: region_name | B10: text | C10: controlled | D10: Yes | E10: Reference | F10: Mapped from code | G10: Display label
A11: asl_code | B11: text | C11: authority code | D11: Regional | E11: Source/map | F11: Required for ASL output | G11: Local authority
A12: distribution_channel | B12: text | C12: CO/DD/DPC/other | D12: Yes | E12: Source/map | F12: Controlled vocabulary | G12: Distribution channel
A13: aic | B13: text | C13: 9 digits | D13: Regional | E13: Source | F13: Leading zero preserved | G13: Pack identifier
A14: atc1 | B14: text | C14: ATC1 | D14: Yes | E14: Source/ref | F14: Hierarchy valid | G14: Anatomical group
A15: atc2 | B15: text | C15: ATC2 | D15: Yes | E15: Source/ref | F15: Hierarchy valid | G15: Therapeutic group
A16: atc3 | B16: text | C16: ATC3 | D16: Yes | E16: Source/ref | F16: Hierarchy valid | G16: Pharmacological group
A17: atc4 | B17: text | C17: ATC4 | D17: Yes | E17: Source/ref | F17: Hierarchy valid | G17: Chemical subgroup
A18: atc5 | B18: text | C18: ATC5 | D18: Regional | E18: Source/ref | F18: Valid if assigned | G18: Substance level
A19: product_description_raw | B19: text | C19: source text | D19: Regional | E19: Source | F19: Never overwritten | G19: Original product description
A20: brand_name | B20: text | C20: controlled | D20: Regional | E20: AIFA/parser | F20: Traceable mapping | G20: Commercial name
... A36: quality_status | B36: text | C36: pass/warn/fail/quarantine | D36: Yes | E36: Pipeline | F36: Controlled value | G36: Publication eligibility

Sheet Module_Data_Matrix
A1: Module-to-data matrix
A2: Minimum data, current evidence and delivery dependencies.
A4: Module | B4: Objective | C4: Minimum inputs | D4: Available now | E4: Missing dependency | F4: First output | G4: Hard boundary
A5: M1 | B5: Spend and consumption | C5: National ATC; regional AIC; official totals | D5: National CSV and Abruzzo DB | E5: New Region extracts and controls | F5: Trend and variance worklist | G5: No patient-level analysis
A6: M2 | B6: Biosimilar and LOE radar | C6: AIC, pack content, DDD, LOE and prices | D6: AIFA AIC, biosimilar reports, Abruzzo flags | E6: Gap resolution, WHO DDD, LOE validation, tenders | F6: Ranked molecule review queue | G6: No substitution recommendation
A7: M3 | B7: Registry/File F governance | C7: M1, File F and Registry exports | D7: M1 foundation | E7: Authority extracts | F7: Discrepancy/deadline worklist | G7: No registry completion
A8: M4 | B8: Stock and shortage | C8: AIC inventory, batches, movements, shortages | D8: Public shortage source | E8: Local warehouse feeds | F8: 30/60/90-day value at risk | G8: No automatic ordering
A9: M5 | B9: Compounding waste | C9: Aggregate preparations, vials and residuals | D9: None | E9: Aggregate centre/day logs | F9: Waste/consolidation scenarios | G9: No individual dose calculation
A10: M6 | B10: Cross-authority comparison | C10: Comparable facts and denominators | D10: National Regions and Abruzzo ASLs | E10: Additional detailed Regions | F10: Persistent peer variance | G10: Variance is not causal proof

Sheet Source_Catalog
A1: Source catalogue
A2: Verified available, public, restricted and client-supplied sources.
A4: ID | B4: Source | C4: Publisher/owner | D4: Granularity | E4: Cadence | F4: Availability | G4: Modules | H4: Purpose / limitation
A5: S01 | B5: DB_Cruscotto_Farmaceutica.xlsx | C5: Abruzzo working group | D5: AIC x ASL x month x channel | E5: Extract | F5: Available | G5: M1,M2,M6 | H5: Detailed development corpus with product text and flags
A6: S02 | B6: Cruscotto_Farmaceutica.xlsx | C6: Abruzzo working group | D6: Analytical views | E6: Manual | F6: Available | G6: M1,M2,M6 | H6: Functional prototype; not a production pipeline
A7: S03 | B7: AIFA/NSIS national CSV | C7: AIFA / Ministry | D7: Region x month x class x ATC1-ATC4 | E7: Monthly | F7: Public 2016+ | G7: M1,M6 | H7: National benchmark; no AIC or ASL
A8: S04 | B8: AIFA biosimilar reports | C8: AIFA | D8: Region x molecule/category | E8: Periodic | F8: Public 2020-2025 archives | G8: M2,M6 | H8: PDF extraction requires page lineage and validation
A9: S05 | B9: AIFA Anagrafica Farmaci | C9: AIFA | D9: AIC x authorised pack | E9: Daily | F9: Public/downloaded | G9: M1,M2,M4 | H9: Product dictionary; not regional utilisation
A10: S06 | B10: AIFA Principi Attivi | C10: AIFA | D10: AIC x ingredient | E10: Daily | F10: Public/downloaded | G10: M1,M2 | H10: Structured quantity/unit coverage is incomplete
A11: S07 | B11: WHO ATC/DDD | C11: WHO Collaborating Centre | D11: ATC x route x DDD | E11: Periodic | F11: Public; pending ingestion | G11: M1,M2 | H11: DDD denominator, not pack content or local price
A12: S08 | B12: Egualia LOE calendar | C12: Egualia | D12: Molecule x theoretical expiry | E12: Annual PDF | F12: Public | G12: M2 | H12: Dates indicative; legal/commercial confirmation required
A13: S09 | B13: Farmadati/equivalent | C13: Licensed provider | D13: AIC x product attributes | E13: Licensed | F13: Conditional | G13: M1,M2 | H13: Gap/validation source after public coverage benchmark
A14: S10 | B14: Authenticated NSIS OSP/DIR | C14: Ministry/authority | D14: Region/ASL x month x AIC x cost/quantity | E14: Monthly | F14: Institutional access | G14: M1,M2,M6 | H14: Request OSP_005/007/009/012 and DIR equivalents
A15: S11 | B15: File F and Registry exports | C15: Participating authority | D15: Operational records | E15: Monthly | F15: Client required | G15: M3 | H15: Minimum lawful fields only
... A29: S25 | B29: AIFA quality defects (Difetti di qualita / Provvedimenti) | C29: AIFA | D29: AIC x lot x restrictive measure | E29: Multiple times per year, per period | F29: Public, VERIFIED-SOURCE | G29: M4 | H29: Real bulk CSV/ODS confirmed. Lot/expiry-adjacent detail beyond our existing shortage list (S17). Exact row count not yet recounted by Claude.

Sheet README
A1: VIS PHARMA COMPASS - Master Database
A2: Governed, non-clinical data foundation for M1-M6. Inputs, reference data, calculations and controls are separated for auditability.
A4: Purpose | B4: Define the complete data foundation required to build M1-M6 and distinguish available data from data still required. | D4: Coverage dashboard
A5: Design boundary | B5: Aggregated organisational and economic outputs only; no treatment, dose or patient-specific substitution recommendation. | D5: Metric | E5: Value | F5: Meaning
A6: Raw-data policy | B6: Original regional and national files remain authoritative. This workbook consolidates schemas, profiles, controls and reusable input tables. | D6: Target modules | E6: 6 | F6: M1-M6
A7: Regional source | B7: DB_Cruscotto_Farmaceutica.xlsx: 261,153 rows across AQ, CH, PE and TE. | D7: Regional raw rows | E7: 261153 | F7: Abruzzo development corpus
A8: National source | B8: AIFA/NSIS Region x month x ATC data, 2016 onward; supplied years 2023-2025. | D8: National rows 2023-25 | E8: 529979 | F8: Supplied ATC-level public data
A9: Product reference | B9: AIFA daily AIC master and active-ingredient CSV downloaded 2026-08-19. | D9: Geographies | E9: 21 | F9: Regions/autonomous provinces
A10: Product-level expansion | B10: Authenticated NSIS OSP/DIR reports or standardized Region/ASL exports are required for complete multi-region AIC facts. | D10: AIFA active-ingredient rows | E10: 72203 | F10: Product-ingredient relations
A11: Refresh principle | B11: Every ingestion must be versioned, reconciled, quality-scored and traceable to source and reporting period. | D11: Distinct AICs | E11: 58496 | F11: Observed in ingredient file
A12: Status | B12: Master database specification v1.1; includes data-entry templates and auditable formulas. | D12: Structured quantity rows | E12: 24034 | F12: Direct dosage quantity available

Sheet AIC_Join_Coverage
A1: AIC Join Coverage — verified against the full Combined data.xlsx (Lufemos/vis repo)
A2: Computed directly from all rows of all sheets, 21 Aug 2026. Not estimated, not sampled.
A4: Measure | B4: Value | C4: Interpretation
A5: Abruzzo distinct AIC codes (normalized, 9-digit) | B5: 5882 | C5: Real product mix actually dispensed, 2024-2026
A6: Matched to AIFA_Products (company/form/ATC known) | B6: 5,759 / 5,882 = 97.9% | C6: Product IDENTITY resolved for nearly all real products
A7: Matched to AIFA_Ingredients, any row | B7: 1,696 / 5,882 = 28.8% | C7: Appears in the public ingredient file at all
A8: Matched to AIFA_Ingredients WITH usable qty+unit | B8: 713 / 5,882 = 12.1% | C8: Real €/mg or €/DDD possible via AIFA's public file alone, TODAY
A9: Free-text parser on Abruzzo's own descriptions | B9: ~70% (from Section 3.3 test) | C9: PRIMARY normalization method — outperforms the AIFA structured join
A11: Revised conclusion | C11: AIFA_Ingredients is a secondary validator for ~12% of real cases, not the primary €/mg path. The free-text parser (or licensed Farmadati) remains load-bearing for the other ~58 points of coverage between the parser's 70% and the structured file's 12%.
A14: UPDATE — full layered parser run against all 5,882 real products, 21 Aug 2026
A15: Combines: AIFA_Ingredients exact match (authoritative) + free-text parser on Abruzzo's own descriptions (5 pattern layers), run against every real product, not a sample.
A17: Method layer | B17: Products resolved | C17: % of 5,882
A18: AIFA_Ingredients exact match (authoritative) | B18: 543 | C18: 9.2% | D18: Bug found+fixed: AIFA uses full words (milligrammi/grammi) not MG/G abbreviations — this layer returned 0 before the fix
A19: Parsed: direct strength (e.g. '30 CPR 50 MG') | B19: 2854 | C19: 48.5% | D19: Validated confidence
A20: Parsed: single value, unit assumed = 1 | B20: 632 | C20: 10.7% | D20: Candidate confidence — lower certainty on unit count
A21: Parsed: volume x concentration (e.g. '10F 1ML 200MG/ML') | B21: 205 | C21: 3.5% | D21: Validated confidence
A22: Parsed: implied single unit + vol/conc | B22: 92 | C22: 1.6% | D22: Candidate confidence
A23: Parsed: percentage + weight (e.g. '3% 14,2G') | B23: 15 | C23: 0.3% | D23: Validated confidence
A25: TOTAL RESOLVED | B25: 4341 | C25: 73.8% | D25: Spend-weighted: EUR 832.4M / EUR 1,076.7M = 77.3%
A26: Unresolved — oxygen/gas products (not mg-applicable) | B26: 82 | C26: 1.4% | D26: Different unit system (litres); needs its own module logic, not mg/DDD
A27: Unresolved — multi-active combination products | B27: 32 | C27: 0.5% | D27: Needs a policy decision on which active substance is 'the' comparator
A28: Unresolved — single-dose device, ambiguous notation | B28: 11 | C28: 0.2% | D28: Deliberately NOT auto-resolved — risk of silently wrong total content; flagged for pharmacist confirmation
A29: Unresolved — other / no pattern matched | B29: 1416 | C29: 24.1% | D29: Genuine remaining gap; candidate for Farmadati license or further parser investment

Sheet AIC_Normalization_Resolved
A1: aic | B1: description | C1: spend_eur | D1: resolved | E1: confidence | F1: method | G1: units | H1: content_per_unit_mg | I1: total_content_mg | J1: source_note
A2: 044885046 | B2: DARZALEX*SC 1FL 15ML 120MG/ML | C2: 26726877.13 | D2: True | E2: Validated | F2: parsed:vol_conc | G2: 1 | H2: 1800.0 | I2: 1800.0 | J2: 1FL 15ML 120MG/ML
A3: 044386023 | B3: KEYTRUDA*INFUS 1FL 4ML 25MG/ML | C3: 23504017.5 | D3: True | E3: Validated | F3: parsed:vol_conc | G3: 1 | H3: 100.0 | I3: 100.0 | J3: 1FL 4ML 25MG/ML
A4: 041663030 | B4: VYNDAQEL*30CPS MOLLI 61MG | C4: 19351875.69 | D4: True | E4: Validated | F4: parsed:direct_strength | G4: 30 | H4: 61.0 | I4: 1830.0 | J4: 30CPS MOLLI 61MG
A5: 048984013 | B5: KAFTRIO*56CPR RIV 100+50+75MG | C5: 17073819.8 | D5: True | E5: Candidate | F5: parsed:single_value_assumed_unit | G5: 1 | H5: 75.0 | I5: 75.0 | J5: 75MG
A6: 045889019 | B6: OCREVUS*INFUS 1FL 300MG 10ML | C6: 16972020.03 | D6: True | E6: Validated | F6: parsed:direct_strength | G6: 1 | H6: 300.0 | I6: 300.0 | J6: 1FL 300MG
A7: 043519053 | B7: KALYDECO*28CPR RIV 150MG | C7: 15147450.39 | D7: True | E7: Validated | F7: parsed:direct_strength | G7: 28 | H7: 150.0 | I7: 4200.0 | J7: 28CPR RIV 150MG
A8: 049328014 | B8: ENHERTU*INF 1FL POLV 100MG | C8: 11645103.97 | D8: True | E8: Validated | F8: parsed:direct_strength | G8: 1 | H8: 100.0 | I8: 100.0 | J8: 1FL POLV 100MG
A9: 044291033 | B9: OPDIVO*INFUS 1FL 24ML 10MG/ML | C9: 11627083.57 | D9: True | E9: Validated | F9: parsed:vol_conc | G9: 1 | H9: 240.0 | I9: 240.0 | J9: 1FL 24ML 10MG/ML
A10: 042868024 | B10: XTANDI*112CPR RIV 40MG | C10: 10602090.06 | D10: True | E10: Validated | F10: parsed:direct_strength | G10: 112 | H10: 40.0 | I10: 4480.0 | J10: 112CPR RIV 40MG
A11: 047525011 | B11: ERLEADA*112CPR RIV 60MG | C11: 9636774.71 | D11: True | E11: Validated | F11: parsed:direct_strength | G11: 112 | H11: 60.0 | I11: 6720.0 | J11: 112CPR RIV 60MG
A12: 042682017 | B12: PERJETA*EV 1F 420MG 30MG/ML | C12: 9211601.92 | D12: True | E12: Validated | F12: parsed:direct_strength | G12: 1 | H12: 420.0 | I12: 420.0 | J12: 1F 420MG
... A19: 043783075 | B19: TRULICITY*4PEN 1,5MG 0,5ML | C19: 7505823.46 | D19: True | E19: Validated | F19: parsed:direct_strength | G19: 4 | H19: 1.5 | I19: 6.0 | J19: 4PEN 1,5MG
A20: 040108033 | B20: PROLIA*SC 1SIR 60MG/ML | C20: 7355782.85 | D20: False | E20: Unresolved | F20: unresolved
A21: 044317030 | B21: REPATHA*SC 2PEN 140MG 1ML | C21: 7126816.57 | D21: True | E21: Validated | F21: parsed:direct_strength | G21: 2 | H21: 140.0 | I21: 280.0 | J21: 2PEN 140MG
A22: 035275015 | B22: FABRAZYME*IV 1FL 35MG | C22: 6982633.71 | D22: True | E22: Validated | F22: parsed:direct_strength | G22: 1 | H22: 35.0 | I22: 35.0 | J22: 1FL 35MG
A23: 038962181 | B23: OSSIGENO*CRIOGEN 31LT MOBILE | C23: 6877871.07 | D23: False | E23: Unresolved | F23: unresolved
A24: 039058045 | B24: OSSIGENO*CRIOGEN 31LT MOBILE | C24: 6794120.61 | D24: False | E24: Unresolved | F24: unresolved
A25: 043827029 | B25: OFEV*60CPS MOLLI 100MG | C25: 6645628.83 | D25: True | E25: Validated | F25: parsed:direct_strength | G25: 60 | H25: 100.0 | I25: 6000.0 | J25: 60CPS MOLLI 100MG
A26: 044315188 | B26: LIXIANA*28CPR RIV 60MG | C26: 6619134.45 | D26: True | E26: Validated | F26: parsed:direct_strength | G26: 28 | H26: 60.0 | I26: 1680.0 | J26: 28CPR RIV 60MG
A27: 048719052 | B27: RYBELSUS*30CPR 7MG | C27: 6529764.47 | D27: True | E27: Validated | F27: parsed:direct_strength | G27: 30 | H27: 7.0 | I27: 210.0 | J27: 30CPR 7MG
A28: 045676273 | B28: DUPIXENT*SC 2PEN 300MG 2ML | C28: 6509617.36 | D28: True | E28: Validated | F28: parsed:direct_strength | G28: 2 | H28: 300.0 | I28: 600.0 | J28: 2PEN 300MG
A29: 046128056 | B29: OZEMPIC*1PEN 1MG/D+4AGHI | C29: 6503751.51 | D29: False | E29: Unresolved | F29: unresolved
A30: 043619030 | B30: XULTOPHY*5PEN 100U/ML+3,6MG/ML | C30: 6261199.25 | D30: False | E30: Unresolved | F30: unresolved
A31: 046773014 | B31: BIKTARVY*30CPR 50+200+25MG FL | C31: 6201259.69 | D31: True | E31: Candidate | F31: parsed:single_value_assumed_unit | G31: 1 | H31: 25.0 | I31: 25.0 | J31: 25MG
A32: 040949051 | B32: GILENYA*28CPS 0,5MG | C32: 6198298.05 | D32: True | E32: Validated | F32: parsed:direct_strength | G32: 28 | H32: 0.5 | I32: 14.0 | J32: 28CPS 0,5MG
A33: 049429032 | B33: KESIMPTA*SC 1PENNA 20MG 0,4ML | C33: 6157102.77 | D33: True | E33: Validated | F33: parsed:direct_strength | G33: 1 | H33: 20.0 | I33: 20.0 | J33: 1PENNA 20MG
A34: 048905020 | B34: REBLOZYL*SC 1FL POLV 75MG | C34: 6070710.45 | D34: True | E34: Validated | F34: parsed:direct_strength | G34: 1 | H34: 75.0 | I34: 75.0 | J34: 1FL POLV 75MG
A35: 045772023 | B35: TREMFYA*SC 1PEN 100MG/1ML | C35: 5976116.37 | D35: False | E35: Unresolved | F35: unresolved
A36: 042494070 | B36: FORXIGA*28CPR RIV 10MG | C36: 5913448.08 | D36: True | E36: Validated | F36: parsed:direct_strength | G36: 28 | H36: 10.0 | I36: 280.0 | J36: 28CPR RIV 10MG
A37: 047821020 | B37: SKYRIZI*SC 1PEN 150MG 1ML | C37: 5716916.07 | D37: True | E37: Validated | F37: parsed:direct_strength | G37: 1 | H37: 150.0 | I37: 150.0 | J37: 1PEN 150MG
A38: 043827043 | B38: OFEV*60CPS MOLLI 150MG | C38: 5659555.87 | D38: True | E38: Validated | F38: parsed:direct_strength | G38: 60 | H38: 150.0 | I38: 9000.0 | J38: 60CPS MOLLI 150MG
A39: 042510014 | B39: EYLEA*INIET 1SIR 40MG/ML | C39: 5602825.33 | D39: False | E39: Unresolved | F39: unresolved
A40: 044891048 | B40: IDELVION*EV FL 2000UI+FL 5ML | C40: 5500257.68 | D40: False | E40: Unresolved | F40: unresolved
A41: 045198076 | B41: VENCLYXTO*112CPR RIV 100MG | C41: 5306938.57 | D41: True | E41: Validated | F41: parsed:direct_strength | G41: 112 | H41: 100.0 | I41: 11200.0 | J41: 112CPR RIV 100MG
A42: 041225032 | B42: ELIQUIS*60CPR RIV 2,5MG | C42: 4960950.68 | D42: True | E42: Validated | F42: parsed:direct_strength | G42: 60 | H42: 2.5 | I42: 150.0 | J42: 60CPR RIV 2,5MG
A43: 044315051 | B43: LIXIANA*28CPR RIV 30MG | C43: 4901630.81 | D43: True | E43: Validated | F43: parsed:direct_strength | G43: 28 | H43: 30.0 | I43: 840.0 | J43: 28CPR RIV 30MG
A44: 043867023 | B44: OTEZLA*56CPR RIV 30MG | C44: 4885818.38 | D44: True | E44: Validated | F44: parsed:direct_strength | G44: 56 | H44: 30.0 | I44: 1680.0 | J44: 56CPR RIV 30MG
A45: 048059036 | B45: ULTOMIRIS*EV 1FL 11ML 100MG/ML | C45: 4825375.83 | D45: True | E45: Validated | F45: parsed:vol_conc | G45: 1 | H45: 1100.0 | I45: 1100.0 | J45: 1FL 11ML 100MG/ML
A46: 049288020 | B46: PHESGO*SC 1F 10ML 600MG+600MG | C46: 4794302.31 | D46: True | E46: Candidate | F46: parsed:single_value_assumed_unit | G46: 1 | H46: 600.0 | I46: 600.0 | J46: 600MG
...

Sheet Second_Pass_Verification
A1: Second-pass gap research (Codex, 21 Aug 2026) — independently re-verified by Claude before entry
A2: Confidence key: VERIFIED-EXACT = fetched/counted by Claude, exact match. VERIFIED-SOURCE = source confirmed real, exact figures not independently recounted. UNVERIFIED = Codex claim only, not yet checked by Claude. CORRECTED = Codex framing found to overstate what independent search confirmed.
A4: Module | B4: Claim | C4: Confidence | D4: What Claude actually did | E4: Practical implication
A5: M7 | B5: AIFA CSE outcomes, July 2026: 116 procedures, 89 in exchange / 21 to Board / 6 concluded | C5: VERIFIED-EXACT | D5: Fetched the real PDF (aifa.gov.it/documents/20142/3884801/...), extracted every row's outcome status with code, counted programmatically. | E5: Safe to treat as fact. Ready to ingest as a monthly reproducible feed for M7's reimbursement-pipeline view.
A6: M3 | B6: AIFA registry list: 376 active, 353 closed | C6: VERIFIED-SOURCE | D6: Fetched the real page and confirmed the bulk CSV/ODS files exist, dated 19 Aug 2026, matching structure. Did not recount every row. | E6: Real, but scope is narrow: this is a catalog of which registries EXIST, not patient-level registry entries. Does not close M3's actual reconciliation need - Codex's own caveat on this point is accurate and preserved.
A7: M2 | B7: "AIFA exact-AIC API" providing a "scalable normalization route"; PROLIA AIC 040108033 resolved to 60mg via official RCP | C7: CORRECTED | D7: Independently searched and found the underlying mechanism: an undocumented internal API behind medicinali.aifa.gov.it, the same citizen search tool already confirmed robots.txt-blocked for bulk access (a third-party GitHub scraper project exists specifically because this API is undocumented). | E7: The specific PROLIA resolution via its official RCP is a valid, reusable manual technique - use it for high-spend ambiguous cases one at a time. It is NOT a scalable bulk route for the remaining ~1,416 products; don't plan M2 completion around this as if it were an API.
A8: M4 | B8: 82 EMA shortage records; 19 AIFA quality-defect measures covering 24 AICs with lot/expiry data | C8: VERIFIED-SOURCE (defects) / UNVERIFIED (EMA count) | D8: Confirmed aifa.gov.it/it/difetti-di-qualita is real with genuine bulk CSV/ODS files per period. Did not open and count a specific file to confirm 19/24. Did not independently check the EMA shortage-record claim at all. | E8: Worth ingesting the AIFA quality-defects feed regardless (it's real and adds lot-level detail our existing S17 shortage list lacks) - but confirm the exact count before quoting '19 measures / 24 AICs' as fact. EMA figure needs a first verification pass, not yet attempted.
A9: M5 | B9: Italian multicentre study: 21 centres, 418 patients, measurable waste/drug-day savings (PMC6463268) | C9: UNVERIFIED | D9: Not yet independently fetched or checked by Claude this pass. | E9: Do not cite the specific 21/418 figures until verified. If real, this is evidence for the sales narrative only (a published study, not a live data feed) - would not change M5's operational verdict of 'client-required' either way.
